# prepare_int_data.py data/local/local_lm/data/text data/local/local_lm/data/work/vocab_wordlist.txt data/local/local_lm/data/work/int_wordlist
# running at Mon May  9 15:06:12 2022
validate_vocab.py: validated file data/local/local_lm/data/work/vocab_wordlist.txt with 196738 entries.
Traceback (most recent call last):
  File "/home/sk5057/kaldi/egs/tamil_telugu_proj/s5_r3/../../../tools/pocolm/scripts/prepare_int_data.py", line 168, in <module>
    num_words = GetNumWords(args.vocab)
  File "/home/sk5057/kaldi/egs/tamil_telugu_proj/s5_r3/../../../tools/pocolm/scripts/prepare_int_data.py", line 75, in GetNumWords
    universal_newlines=True)
  File "/usr/lib/python3.6/subprocess.py", line 356, in check_output
    **kwargs).stdout
  File "/usr/lib/python3.6/subprocess.py", line 425, in run
    stdout, stderr = process.communicate(input, timeout=timeout)
  File "/usr/lib/python3.6/subprocess.py", line 850, in communicate
    stdout = self.stdout.read()
  File "/usr/lib/python3.6/encodings/ascii.py", line 26, in decode
    return codecs.ascii_decode(input, self.errors)[0]
UnicodeDecodeError: 'ascii' codec can't decode byte 0xe0 in position 0: ordinal not in range(128)
# exited with return code 1 after 0.5 seconds
